Workbook

Sheet Progress Dashboard
A1: NexaRemit Rollout — Progress Dashboard
A2: Live executive view. All counts and statuses pull from the Recommendations sheet. Rollout week counter reads cell C4 — update it weekly to keep the timeline accurate.
B4: Current Rollout Week # | C4: 1 | D4: Rollout Start Date | E4: 2026-07-06 | F4: Report Date | G4: =E4+(C4-1)*7 -> 46209
A6: Status Snapshot — All Recommendations
B7: Total Recommendations | D7: Done | F7: In Progress | H7: Not Started
B8: =COUNTA(Recommendations!B4:B13) -> 10 | D8: =COUNTIF(Recommendations!H4:H13,"Done") -> 0 | F8: =COUNTIF(Recommendations!H4:H13,"In Progress") -> 10 | H8: =COUNTIF(Recommendations!H4:H13,"Not Started") -> 0
B9: of total | D9: =_xlfn.IFERROR(COUNTIF(Recommendations!H4:H13,"Done")/COUNTA(Recommendations!B4:B13),0) -> 0 | F9: =_xlfn.IFERROR(COUNTIF(Recommendations!H4:H13,"In Progress")/COUNTA(Recommendations!B4:B13),0) -> 1 | H9: =_xlfn.IFERROR(COUNTIF(Recommendations!H4:H13,"Not Started")/COUNTA(Recommendations!B4:B13),0) -> 0
A10: Completion progress = Done / Total. Update Recommendations column H as items ship.
A12: Priority × Status Rollup
B13: Priority | C13: Total | D13: Done | E13: In Progress | F13: Not Started | G13: % Done | H13: Health | I13: Target Completion | J13: Notes
B14: P1 — Do Now | C14: =COUNTIF(Recommendations!C4:C13,"P1") -> 5 | D14: =_xlfn.COUNTIFS(Recommendations!C4:C13,"P1",Recommendations!H4:H13,"Done") -> 0 | E14: =_xlfn.COUNTIFS(Recommendations!C4:C13,"P1",Recommendations!H4:H13,"In Progress") -> 5 | F14: =_xlfn.COUNTIFS(Recommendations!C4:C13,"P1",Recommendations!H4:H13,"Not Started") -> 0 | G14: =_xlfn.IFERROR(D14/C14,0) -> 0 | H14: =IF(G14>=1,"On Track",IF($C$4<=2,"On Track",IF(G14>=0.5,"At Risk","Blocked"))) -> On Track | I14: Week 2 | J14: Hero pricing + Mexico/PH/India + Quote Capture
B15: P2 — Next | C15: =COUNTIF(Recommendations!C4:C13,"P2") -> 3 | D15: =_xlfn.COUNTIFS(Recommendations!C4:C13,"P2",Recommendations!H4:H13,"Done") -> 0 | E15: =_xlfn.COUNTIFS(Recommendations!C4:C13,"P2",Recommendations!H4:H13,"In Progress") -> 3 | F15: =_xlfn.COUNTIFS(Recommendations!C4:C13,"P2",Recommendations!H4:H13,"Not Started") -> 0 | G15: =_xlfn.IFERROR(D15/C15,0) -> 0 | H15: =IF(G15>=1,"On Track",IF($C$4<=4,"On Track",IF(G15>=0.5,"At Risk","Blocked"))) -> On Track | I15: Week 6 | J15: Calculator + Guardrails + Next Corridor
B16: P3 — Later | C16: =COUNTIF(Recommendations!C4:C13,"P3") -> 2 | D16: =_xlfn.COUNTIFS(Recommendations!C4:C13,"P3",Recommendations!H4:H13,"Done") -> 0 | E16: =_xlfn.COUNTIFS(Recommendations!C4:C13,"P3",Recommendations!H4:H13,"In Progress") -> 2 | F16: =_xlfn.COUNTIFS(Recommendations!C4:C13,"P3",Recommendations!H4:H13,"Not Started") -> 0 | G16: =_xlfn.IFERROR(D16/C16,0) -> 0 | H16: =IF(G16>=1,"On Track",IF($C$4<=6,"On Track",IF(G16>=0.5,"At Risk","Blocked"))) -> On Track | I16: Week 6 | J16: Legacy benchmarks + Promo tracking
B17: TOTAL | C17: =SUM(C14:C16) -> 10 | D17: =SUM(D14:D16) -> 0 | E17: =SUM(E14:E16) -> 10 | F17: =SUM(F14:F16) -> 0 | G17: =_xlfn.IFERROR(D17/C17,0) -> 0 | H17: =IF(G17>=1,"Complete",IF(G17>=0.75,"Nearly Done",IF(G17>=0.5,"Halfway","Early"))) -> Early | I17: Week 6 all-in
A18: Health = 'On Track' if Done ≥ 100% OR still within target week window. 'At Risk' if ≥ 50% done past target. 'Blocked' otherwise.
A20: Timeline Tracker — Target Week vs Current Week
A21: # | B21: Recommendation | C21: Priority | D21: Owner | E21: Target Week | F21: Weeks Elapsed | G21: Weeks Remaining | H21: Status | I21: Signal | J21: Detail Sheet
A22: 1 | B22: =Recommendations!B4 -> Launch Hero pricing on Nigeria, Ghana, Kenya at $0 fee | C22: =Recommendations!C4 -> P1 | D22: =Recommendations!G4 -> Growth + Pricing | E22: 2 | F22: =$C$4 -> 1 | G22: =E22-F22 -> 1 | H22: =Recommendations!H4 -> In Progress | I22: =IF(H22="Done","✓ Complete",IF(G22<0,"⚠ Overdue",IF(G22<=1,"⏰ Due Soon","● On Schedule"))) -> ⏰ Due Soon | J22: P1 Implementation
A23: 2 | B23: =Recommendations!B5 -> Beat Remitly on Mexico with fee ≤ $0.99 | C23: =Recommendations!C5 -> P1 | D23: =Recommendations!G5 -> Pricing | E23: 2 | F23: =$C$4 -> 1 | G23: =E23-F23 -> 1 | H23: =Recommendations!H5 -> In Progress | I23: =IF(H23="Done","✓ Complete",IF(G23<0,"⚠ Overdue",IF(G23<=1,"⏰ Due Soon","● On Schedule"))) -> ⏰ Due Soon | J23: P1 Implementation
A24: 3 | B24: =Recommendations!B6 -> Undercut Xoom on Philippines all-in cost | C24: =Recommendations!C6 -> P1 | D24: =Recommendations!G6 -> Product + Pricing | E24: 3 | F24: =$C$4 -> 1 | G24: =E24-F24 -> 2 | H24: =Recommendations!H6 -> In Progress | I24: =IF(H24="Done","✓ Complete",IF(G24<0,"⚠ Overdue",IF(G24<=1,"⏰ Due Soon","● On Schedule"))) -> ● On Schedule | J24: P1 Implementation
A25: 4 | B25: =Recommendations!B7 -> Attack India (INR) on FX spread, not fee | C25: =Recommendations!C7 -> P1 | D25: =Recommendations!G7 -> Pricing + Engineering | E25: 3 | F25: =$C$4 -> 1 | G25: =E25-F25 -> 2 | H25: =Recommendations!H7 -> In Progress | I25: =IF(H25="Done","✓ Complete",IF(G25<0,"⚠ Overdue",IF(G25<=1,"⏰ Due Soon","● On Schedule"))) -> ● On Schedule | J25: P1 Implementation
A26: 5 | B26: =Recommendations!B8 -> Capture live $100 competitor quotes weekly | C26: =Recommendations!C8 -> P1 | D26: =Recommendations!G8 -> Ops | E26: 1 | F26: =$C$4 -> 1 | G26: =E26-F26 -> 0 | H26: =Recommendations!H8 -> In Progress | I26: =IF(H26="Done","✓ Complete",IF(G26<0,"⚠ Overdue",IF(G26<=1,"⏰ Due Soon","● On Schedule"))) -> ⏰ Due Soon | J26: P1 Implementation
A27: 6 | B27: =Recommendations!B9 -> Publish a public 'Total Cost' calculator | C27: =Recommendations!C9 -> P2 | D27: =Recommendations!G9 -> Product | E27: 4 | F27: =$C$4 -> 1 | G27: =E27-F27 -> 3 | H27: =Recommendations!H9 -> In Progress | I27: =IF(H27="Done","✓ Complete",IF(G27<0,"⚠ Overdue",IF(G27<=1,"⏰ Due Soon","● On Schedule"))) -> ● On Schedule | J27: P2 Implementation
A28: 7 | B28: =Recommendations!B10 -> Enforce Guardrails from Strategy sheet in code | C28: =Recommendations!C10 -> P2 | D28: =Recommendations!G10 -> Engineering | E28: 6 | F28: =$C$4 -> 1 | G28: =E28-F28 -> 5 | H28: =Recommendations!H10 -> In Progress | I28: =IF(H28="Done","✓ Complete",IF(G28<0,"⚠ Overdue",IF(G28<=1,"⏰ Due Soon","● On Schedule"))) -> ● On Schedule | J28: P2 Implementation
A29: 8 | B29: =Recommendations!B11 -> Fill the 'Other' corridor with the next launch market | C29: =Recommendations!C11 -> P2 | D29: =Recommendations!G11 -> Strategy | E29: 4 | F29: =$C$4 -> 1 | G29: =E29-F29 -> 3 | H29: =Recommendations!H11 -> In Progress | I29: =IF(H29="Done","✓ Complete",IF(G29<0,"⚠ Overdue",IF(G29<=1,"⏰ Due Soon","● On Schedule"))) -> ● On Schedule | J29: P2 Implementation
A30: 9 | B30: =Recommendations!B12 -> Add Western Union + MoneyGram as reference competitors | C30: =Recommendations!C12 -> P3 | D30: =Recommendations!G12 -> Ops | E30: 4 | F30: =$C$4 -> 1 | G30: =E30-F30 -> 3 | H30: =Recommendations!H12 -> In Progress | I30: =IF(H30="Done","✓ Complete",IF(G30<0,"⚠ Overdue",IF(G30<=1,"⏰ Due Soon","● On Schedule"))) -> ● On Schedule | J30: P3 Implementation
A31: 10 | B31: =Recommendations!B13 -> Track promotional first-transfer rates separately | C31: =Recommendations!C13 -> P3 | D31: =Recommendations!G13 -> Analytics | E31: 6 | F31: =$C$4 -> 1 | G31: =E31-F31 -> 5 | H31: =Recommendations!H13 -> In Progress | I31: =IF(H31="Done","✓ Complete",IF(G31<0,"⚠ Overdue",IF(G31<=1,"⏰ Due Soon","● On Schedule"))) -> ● On Schedule | J31: P3 Implementation
A32: Weeks Remaining = Target Week − Current Week (cell C4). Update C4 weekly to refresh Signal column.
A34: Top Blockers — Items Overdue or Due This Week
A35: Rank | B35: Recommendation | C35: Priority | D35: Owner | E35: Weeks Overdue | F35: Immediate Next Step
A36: 1 | B36: Capture live $100 competitor quotes weekly | C36: P1 | D36: Ops | E36: =MAX(0,$C$4-1) -> 0 | F36: Assign an ops owner today. Log into Wise, Remitly, WorldRemit, Xoom, TapTap Send with send=$100 for all 6 corridors. Populate P1 Implementation rows 42–77.
A37: 2 | B37: Launch Hero pricing on Nigeria, Ghana, Kenya at $0 fee | C37: P1 | D37: Growth + Pricing | E37: =MAX(0,$C$4-2) -> 0 | F37: Publish $0-fee corridor landing pages with FX markup cap ≤ 1.25%. Verify Margin Check column in P1 Implementation rows 7–9 all read 'OK ≥ $0.35'.
A38: 3 | B38: Beat Remitly on Mexico with fee ≤ $0.99 | C38: P1 | D38: Pricing | E38: =MAX(0,$C$4-2) -> 0 | F38: Set MXN corridor fee to $0.99, cap FX markup at 1.00%. Confirm Verdict in P1 Implementation row 16 reads 'NexaRemit wins'. Then A/B test $0.99 vs $0.00 for 4 weeks.
A39: Weeks Overdue = MAX(0, Current Week − Target Week). Refresh weekly. When any of these items ship, mark it 'Done' in Recommendations column H and the blocker will roll off next refresh.
A41: Quick Jump — Detail Sheets
B42: Sheet | C42: Purpose | D42: Contents | G42: Status | H42: When to Open
A43: → | B43: Recommendations | C43: Action tracker | D43: 10 items with Priority, Effort, Status | G43: Live | H43: Update Status column H after each ship
A44: → | B44: P1 Implementation | C44: Immediate work | D44: Hero pricing, Mexico/PH/India workbenches, Weekly Quote Capture | G44: Live | H44: Weekly on Monday for quote capture
A45: → | B45: P2 Implementation | C45: Mid-term work | D45: Calculator spec, Guardrails-as-code, Next-corridor scorecard | G45: Live | H45: When ready to ship calculator or automate guardrails
A46: → | B46: P3 Implementation | C46: Long-term work | D46: Legacy benchmarks, Promo classification | G46: Live | H46: After P1 weekly capture running 4+ weeks
...

Sheet Comparison Matrix
A1: Remittance Pricing Comparison – Send USD 100 from United States
A2: Data collected 2026-07-06. Public provider pages only. Values marked N/A where no public quote is available without login. Not financial advice.
A3: Corridor | B3: Provider | C3: Send Amount USD | D3: Transfer Fee USD | E3: Exchange Rate (1 USD →) | F3: Recipient Amount | G3: Total Charged USD | H3: Total Cost % of Send Amount | I3: Speed / Delivery Estimate | J3: Receive Method / Notes | K3: Date Checked | L3: Source URL | M3: Quote Confidence | N3: Comment
A4: USD → Nigeria (NGN)
A5: Nigeria (NGN) | B5: NexaRemit | C5: 100 | D5: N/A | E5: N/A | F5: N/A | G5: N/A | H5: N/A | I5: N/A | J5: N/A | K5: 2026-07-06 | L5: Placeholder — pricing pending launch | M5: https://nexaremit.com | N5: N/A (internal)
A6: Nigeria (NGN) | B6: TapTap Send | C6: 100 | E6: N/A | F6: N/A | G6: =C6+D6 -> 100 | H6: =D6/C6 -> 0 | I6: Minutes to same day | J6: Bank deposit; $0 transfer fee marketed | K6: 2026-07-06 | L6: www.taptapsend.com | M6: Medium (public marketing page) | N6: TapTap advertises $0 fee to Nigeria; FX markup embedded in rate. Live FX not published on landing page.
A7: Nigeria (NGN) | B7: Wise | C7: 100 | D7: N/A | E7: N/A | F7: N/A | G7: N/A | H7: N/A | I7: Same day typical | J7: Bank deposit; Wise uses mid-market rate + fee | K7: 2026-07-06 | L7: wise.com | M7: N/A (login required for $100 quote) | N7: Public page shows $1,000 example (≈$6.48 fee). $100 quote not shown without login.
A8: Nigeria (NGN) | B8: Remitly | C8: 100 | D8: N/A | E8: N/A | F8: N/A | G8: N/A | H8: N/A | I8: Minutes (Express) / 3-5 business days (Economy) | J8: Bank deposit / mobile wallet | K8: 2026-07-06 | L8: www.remitly.com | M8: N/A (login required for exact $100 quote) | N8: Promotional first-transfer rate common; standard fee/FX not shown without login.
A9: Nigeria (NGN) | B9: WorldRemit | C9: 100 | D9: N/A | E9: N/A | F9: N/A | G9: N/A | H9: N/A | I9: Minutes to hours | J9: Bank deposit / mobile money | K9: 2026-07-06 | L9: www.worldremit.com | M9: Low (indicative only) | N9: WorldRemit indicates possibly $0 fee to Nigeria for some payout methods; live quote requires calculator.
A10: Nigeria (NGN) | B10: Xoom | C10: 100 | D10: N/A | E10: N/A | F10: N/A | G10: N/A | H10: N/A | I10: Minutes typical | J10: Bank deposit / cash pickup | K10: 2026-07-06 | L10: www.xoom.com | M10: N/A (login required) | N10: Fees depend on funding source (bank/debit/credit); FX includes spread.
A11: USD → Ghana (GHS)
A12: Ghana (GHS) | B12: NexaRemit | C12: 100 | D12: N/A | E12: N/A | F12: N/A | G12: N/A | H12: N/A | I12: N/A | J12: Placeholder | K12: 2026-07-06 | L12: nexaremit.com | M12: N/A (internal) | N12: Fill in once public.
A13: Ghana (GHS) | B13: TapTap Send | C13: 100 | E13: N/A | F13: N/A | G13: =C13+D13 -> 100 | H13: =D13/C13 -> 0 | I13: Minutes to same day | J13: Mobile money / bank; $0 fee marketed | K13: 2026-07-06 | L13: www.taptapsend.com | M13: Medium (public marketing page) | N13: $0 transfer fee marketed to Ghana; FX markup embedded.
A14: Ghana (GHS) | B14: Wise | C14: 100 | D14: N/A | E14: N/A | F14: N/A | G14: N/A | H14: N/A | I14: Same day typical | J14: Bank deposit | K14: 2026-07-06 | L14: wise.com | M14: N/A (login required) | N14: Public $100 quote not shown without login.
A15: Ghana (GHS) | B15: Remitly | C15: 100 | D15: N/A | E15: N/A | F15: N/A | G15: N/A | H15: N/A | I15: Minutes (Express) / few days (Economy) | J15: Bank deposit / mobile money | K15: 2026-07-06 | L15: www.remitly.com | M15: N/A (login required) | N15: Promo rate on first send common.
A16: Ghana (GHS) | B16: WorldRemit | C16: 100 | D16: N/A | E16: N/A | F16: N/A | G16: N/A | H16: N/A | I16: Minutes to hours | J16: Mobile money / bank | K16: 2026-07-06 | L16: www.worldremit.com | M16: Low (indicative only) | N16: Public calculator required for live quote.
A17: Ghana (GHS) | B17: Xoom | C17: 100 | D17: N/A | E17: N/A | F17: N/A | G17: N/A | H17: N/A | I17: Minutes typical | J17: Bank / mobile money | K17: 2026-07-06 | L17: www.xoom.com | M17: N/A (login required) | N17: Fees vary by funding source.
A18: USD → India (INR)
A19: India (INR) | B19: NexaRemit | C19: 100 | D19: N/A | E19: N/A | F19: N/A | G19: N/A | H19: N/A | I19: N/A | J19: Placeholder | K19: 2026-07-06 | L19: nexaremit.com | M19: N/A (internal) | N19: Fill in once public.
A20: India (INR) | B20: TapTap Send | C20: 100 | D20: N/A | E20: N/A | F20: N/A | G20: N/A | H20: N/A | I20: Same day typical | J20: Bank deposit (if supported) | K20: 2026-07-06 | L20: www.taptapsend.com | M20: Low (indicative only) | N20: Verify India corridor availability on TapTap; not on all landing pages.
A21: India (INR) | B21: Wise | C21: 100 | D21: N/A | E21: N/A | F21: N/A | G21: N/A | H21: N/A | I21: Same day typical | J21: Bank deposit (UPI/IMPS) | K21: 2026-07-06 | L21: wise.com | M21: N/A (login required for $100 quote) | N21: Public page shows fee examples for larger amounts; $100 quote requires login.
A22: India (INR) | B22: Remitly | C22: 100 | D22: N/A | E22: N/A | F22: N/A | G22: N/A | H22: N/A | I22: Minutes (Express) / few days (Economy) | J22: Bank deposit / UPI | K22: 2026-07-06 | L22: www.remitly.com | M22: N/A (login required) | N22: Frequent promo rate on first send.
A23: India (INR) | B23: WorldRemit | C23: 100 | D23: N/A | E23: N/A | F23: N/A | G23: N/A | H23: N/A | I23: Minutes to hours | J23: Bank deposit | K23: 2026-07-06 | L23: www.worldremit.com | M23: Low (indicative only) | N23: Live quote via calculator only.
A24: India (INR) | B24: Xoom | C24: 100 | D24: N/A | E24: N/A | F24: N/A | G24: N/A | H24: N/A | I24: Minutes typical | J24: Bank deposit / debit card | K24: 2026-07-06 | L24: www.xoom.com | M24: N/A (login required) | N24: FX spread often 2.5–4% on INR per third-party comparison.
A25: USD → Kenya (KES)
A26: Kenya (KES) | B26: NexaRemit | C26: 100 | D26: N/A | E26: N/A | F26: N/A | G26: N/A | H26: N/A | I26: N/A | J26: Placeholder | K26: 2026-07-06 | L26: nexaremit.com | M26: N/A (internal) | N26: Fill in once public.
A27: Kenya (KES) | B27: TapTap Send | C27: 100 | E27: N/A | F27: N/A | G27: =C27+D27 -> 100 | H27: =D27/C27 -> 0 | I27: Minutes to same day | J27: M-Pesa / bank; $0 fee marketed | K27: 2026-07-06 | L27: www.taptapsend.com | M27: Medium (public marketing page) | N27: $0 transfer fee marketed; FX markup embedded.
A28: Kenya (KES) | B28: Wise | C28: 100 | D28: N/A | E28: N/A | F28: N/A | G28: N/A | H28: N/A | I28: Same day typical | J28: Bank / mobile money | K28: 2026-07-06 | L28: wise.com | M28: N/A (login required) | N28: $100 quote requires login.
A29: Kenya (KES) | B29: Remitly | C29: 100 | D29: N/A | E29: N/A | F29: N/A | G29: N/A | H29: N/A | I29: Minutes (Express) / days (Economy) | J29: M-Pesa / bank | K29: 2026-07-06 | L29: www.remitly.com | M29: N/A (login required) | N29: Promo rate on first send common.
A30: Kenya (KES) | B30: WorldRemit | C30: 100 | D30: N/A | E30: N/A | F30: N/A | G30: N/A | H30: N/A | I30: Minutes to hours | J30: M-Pesa / bank | K30: 2026-07-06 | L30: www.worldremit.com | M30: Low (indicative only) | N30: WorldRemit page shows 1 USD ≈ 127.908 KES as of retrieval; live quote via calculator.
A31: Kenya (KES) | B31: Xoom | C31: 100 | D31: N/A | E31: N/A | F31: N/A | G31: N/A | H31: N/A | I31: Minutes typical | J31: Bank / mobile money | K31: 2026-07-06 | L31: www.xoom.com | M31: N/A (login required) | N31: Fees vary by funding source.
A32: USD → Philippines (PHP)
A33: Philippines (PHP) | B33: NexaRemit | C33: 100 | D33: N/A | E33: N/A | F33: N/A | G33: N/A | H33: N/A | I33: N/A | J33: Placeholder | K33: 2026-07-06 | L33: nexaremit.com | M33: N/A (internal) | N33: Fill in once public.
A34: Philippines (PHP) | B34: TapTap Send | C34: 100 | D34: N/A | E34: N/A | F34: N/A | G34: N/A | H34: N/A | I34: Same day typical | J34: Bank / e-wallet (if supported) | K34: 2026-07-06 | L34: www.taptapsend.com | M34: Low (indicative only) | N34: Confirm PH corridor availability.
A35: Philippines (PHP) | B35: Wise | C35: 100 | D35: N/A | E35: N/A | F35: N/A | G35: N/A | H35: N/A | I35: Same day typical | J35: Bank / e-wallet | K35: 2026-07-06 | L35: wise.com | M35: N/A (login required for $100 quote) | N35: Public page shows $1,000 example ≈ $6.98 fee.
A36: Philippines (PHP) | B36: Remitly | C36: 100 | D36: N/A | E36: N/A | F36: N/A | G36: N/A | H36: N/A | I36: Minutes (Express) / days (Economy) | J36: Bank / e-wallet / cash pickup | K36: 2026-07-06 | L36: www.remitly.com | M36: N/A (login required) | N36: Promo rate on first send common.
A37: Philippines (PHP) | B37: WorldRemit | C37: 100 | D37: N/A | E37: N/A | F37: N/A | G37: N/A | H37: N/A | I37: Minutes to hours | J37: Bank / e-wallet / cash pickup | K37: 2026-07-06 | L37: www.worldremit.com | M37: Low (indicative only) | N37: Blog reference cites ~$0.99 fee for some PH transfers; verify via live calculator.
A38: Philippines (PHP) | B38: Xoom | C38: 100 | E38: N/A | F38: N/A | G38: =C38+D38 -> 100 | H38: =D38/C38 -> 0 | I38: Minutes typical | J38: Bank / cash pickup; $0 fee marketed on eligible transactions | K38: 2026-07-06 | L38: www.xoom.com | M38: Medium (public marketing page) | N38: Xoom advertises $0 transfer fees on eligible PH transactions; FX spread applies.
A39: USD → Mexico (MXN)
A40: Mexico (MXN) | B40: NexaRemit | C40: 100 | D40: N/A | E40: N/A | F40: N/A | G40: N/A | H40: N/A | I40: N/A | J40: Placeholder | K40: 2026-07-06 | L40: nexaremit.com | M40: N/A (internal) | N40: Fill in once public.
...

Sheet Methodology
A1: Methodology & Data Notes
A3: Item | B3: Description | C3: Date | D3: Source URL
A4: Scope | B4: Send USD 100 from the United States to 6 destination corridors (Nigeria, Ghana, India, Kenya, Philippines, Mexico) plus one placeholder 'Other' corridor. Providers: NexaRemit, TapTap Send, Wise, Remitly, WorldRemit, Xoom. | C4: 2026-07-06
A5: Data source | B5: Public provider marketing/pricing pages only. No login was used, so exact quotes for a specific $100 send that require sign-in are marked N/A. | C5: 2026-07-06
A6: Homepage claims vs quotes | B6: Marketing claims like '$0 transfer fee' are recorded as Medium confidence and not treated as guaranteed final quotes. Corridor-specific quote pages are always preferred over homepage claims. | C6: 2026-07-06
A7: Volatility | B7: Live FX rates and promotional first-transfer rates change intraday. Same-day comparisons may differ from what a user actually sees at checkout. | C7: 2026-07-06
A8: Fee vs FX markup | B8: Total cost of a remittance = transfer fee + FX markup (mid-market rate vs offered rate). Providers advertising $0 fee typically recover margin inside the FX rate. | C8: 2026-07-06
A9: Confidence levels | B9: High = live public quote captured. Medium = value from public marketing page. Low = indicative only, from third-party sources. N/A = login required or corridor not supported publicly. | C9: 2026-07-06
A10: Ranking method | B10: Cheapest per corridor is determined by lowest Total Charged USD (send + fee) among rows with numeric fee data. Where only marketed $0-fee providers have numeric data, they win by default; FX markup is not fully comparable across providers without live quotes. | C10: 2026-07-06
A11: TapTap Send | B11: US send fee stated as $2.99 in FAQ; landing pages for Nigeria/Ghana/Kenya market $0 transfer fee. Recorded as $0 where the corridor landing page shows $0, otherwise N/A. | C11: 2026-07-06 | D11: support.taptapsend.com
A12: Wise | B12: Public pages show $1,000 example fees, e.g., Nigeria ≈ $6.48, Mexico ≈ $6.43, Philippines ≈ $6.98. $100 quote generally requires login. | C12: 2026-07-06 | D12: wise.com
A13: Remitly | B13: Wise's third-party blog cites Remitly transfer fee to Mexico at $1.99 as typical. Exact $100 corridor quotes require login. | C13: 2026-07-06 | D13: wise.com
A14: WorldRemit | B14: Corridor pages show sample rates (e.g., 1 USD ≈ 127.908 KES to Kenya) but require the calculator for a specific $100 quote. | C14: 2026-07-06 | D14: www.worldremit.com
A15: Xoom | B15: Marketing pages advertise $0 transfer fees on eligible transactions for Mexico and Philippines. Fees vary by funding source (bank vs debit vs credit); FX includes spread. | C15: 2026-07-06 | D15: www.xoom.com
A16: NexaRemit | B16: Internal — placeholder rows in the Comparison Matrix are for NexaRemit's target public pricing per corridor. See NexaRemit Strategy sheet. | C16: 2026-07-06 | D16: nexaremit.com

Sheet NexaRemit Strategy
A1: NexaRemit Target Pricing Strategy
A2: Two-tier approach: 'Hero corridors' win on headline price to acquire users; 'Core corridors' maintain low fee + competitive FX to protect margin. Values are targets, not final published pricing.
A3: Corridor | B3: Tier | C3: Target Transfer Fee (USD) | D3: Target FX Markup vs Mid-Market | E3: Positioning vs Competition | F3: Rationale | G3: Notes / KPIs
A4: Nigeria (NGN) | B4: Hero | C4: $0.00 | D4: 0.75%–1.25% | E4: Match TapTap $0 fee; beat on FX transparency | F4: Large diaspora + strong TapTap presence; win headline 'no-fee' narrative | G4: Watch NGN volatility; monitor CAC vs LTV.
A5: Ghana (GHS) | B5: Hero | C5: $0.00 | D5: 0.75%–1.25% | E5: Match TapTap $0 fee; superior speed to mobile money | F5: Similar dynamics to Nigeria; mobile-money-first market | G5: Track mobile money success rate.
A6: Kenya (KES) | B6: Hero | C6: $0.00 | D6: 0.75%–1.25% | E6: Match TapTap $0 fee; win on M-Pesa reliability | F6: High mobile-money penetration; speed and reliability matter | G6: Track M-Pesa payout SLA.
A7: Philippines (PHP) | B7: Core | C7: $0.99 | D7: 0.50%–1.00% | E7: Beat Xoom on FX spread; near-parity on fee | F7: Xoom advertises $0 eligible; use slightly-nonzero fee + tighter FX to still beat all-in cost | G7: Track e-wallet vs bank mix.
A8: Mexico (MXN) | B8: Core | C8: $0.99 | D8: 0.50%–1.00% | E8: Beat Remitly ($1.99) and Xoom on all-in cost | F8: Very competitive US→MX market; small fee + tight FX preserves unit economics | G8: Monitor promo abuse and repeat rate.
A9: India (INR) | B9: Core | C9: $1.49 | D9: 0.50%–1.00% | E9: Beat Xoom FX spread (often 2.5–4% on INR) | F9: UPI/IMPS makes settlement cheap; FX spread is the differentiator | G9: Track average recipient amount vs. competitors.
A10: Other (TBD) | B10: TBD | C10: TBD | D10: TBD | E10: To be defined | F10: Reserved for the next corridor rollout | G10: Pending corridor selection.
A13: Guardrails
A14: Minimum contribution margin per transfer | B14: >= $0.35 after processor + FX + payout costs at send=USD 100
A15: Cap on Hero corridor losses | B15: Aggregate monthly loss on hero corridors <= marketing budget allocated
A16: Trigger to move corridor to Core | B16: 3 consecutive months of negative unit margin or competitive fee > $1.99
A17: Trigger to move corridor to Hero | B17: Corridor volume > threshold AND competitor headline is $0 fee

Sheet Recommendations
A1: NexaRemit — Prioritized Recommendations
A2: Ranked actions derived from the Comparison Matrix and NexaRemit Strategy sheets. Priority = P1 (do now) → P3 (later). Owner is indicative; adjust to your org.
A3: # | B3: Recommendation | C3: Priority | D3: Effort | E3: Why (Evidence) | F3: Concrete Next Step | G3: Suggested Owner | H3: Status
A4: 1 | B4: Launch Hero pricing on Nigeria, Ghana, Kenya at $0 fee | C4: P1 | D4: Medium | E4: TapTap Send markets $0 fee on all three corridors (Comparison Matrix rows 6, 13, 27). Matching the headline removes the biggest acquisition objection in these diaspora corridors. | F4: Publish $0-fee landing pages per corridor with a 0.75–1.25% FX markup cap. Instrument checkout to log actual FX vs mid-market. | G4: Growth + Pricing | H4: In Progress
A5: 2 | B5: Beat Remitly on Mexico with fee ≤ $0.99 | C5: P1 | D5: Low | E5: Remitly's typical US→MX fee is $1.99 (Comparison Matrix row 43). A $0.99 fee + tighter FX beats Remitly on all-in cost without a full $0 headline. | F5: Set MXN corridor fee to $0.99 and cap FX markup at 1.00%. A/B test $0.99 vs $0.00 for 4 weeks. | G5: Pricing | H5: In Progress
A6: 3 | B6: Undercut Xoom on Philippines all-in cost | C6: P1 | D6: Low | E6: Xoom advertises $0 fee on eligible PH transactions (Comparison Matrix row 38) but FX spread applies. Beating Xoom on FX (not fee) is the winning wedge. | F6: Publish PHP corridor at $0.99 fee + ≤0.75% FX. Show side-by-side 'You save $X vs Xoom' widget on checkout. | G6: Product + Pricing | H6: In Progress
A7: 4 | B7: Attack India (INR) on FX spread, not fee | C7: P1 | D7: Medium | E7: Third-party comparisons cite Xoom FX spread of 2.5–4% on INR (Comparison Matrix row 24). UPI/IMPS settlement makes tight FX affordable. | F7: Launch INR corridor at $1.49 fee + ≤1.00% FX markup. Add a live 'mid-market vs our rate' display on the quote screen. | G7: Pricing + Engineering | H7: In Progress
A8: 5 | B8: Capture live $100 competitor quotes weekly | C8: P1 | D8: Low | E8: 27 of 42 provider cells in the Comparison Matrix are N/A because $100 quotes require login (rows 7–10, 14–17, etc.). Without live quotes, the ranking table only reflects marketed $0-fee providers. | F8: Assign a weekly ops task to log into each competitor and capture $100 quote for all 6 corridors. Paste into Comparison Matrix; formulas auto-recalculate. | G8: Ops | H8: In Progress
A9: 6 | B9: Publish a public 'Total Cost' calculator | C9: P2 | D9: Medium | E9: Every competitor requires login for exact quotes. A public calculator that shows fee + FX markup + recipient amount without signup is a trust differentiator. | F9: Ship /pricing calculator on nexaremit.com with mid-market rate reference and 'You save vs [competitor]' comparison per corridor. | G9: Product | H9: In Progress
A10: 7 | B10: Enforce Guardrails from Strategy sheet in code | C10: P2 | D10: Medium | E10: NexaRemit Strategy rows 14–17 define minimum margin, hero-loss cap, and tier-move triggers. These must be enforced automatically, not reviewed monthly in a spreadsheet. | F10: Add a pricing service that (a) rejects quotes with margin < $0.35, (b) alerts when hero-corridor monthly loss > budget, (c) auto-flags corridors for tier review. | G10: Engineering | H10: In Progress
A11: 8 | B11: Fill the 'Other' corridor with the next launch market | C11: P2 | D11: Low | E11: Comparison Matrix rows 47–52 are input-ready but unassigned. Choosing the next corridor early lets pricing and ops prepare in parallel. | F11: Pick one of {Bangladesh, Pakistan, Senegal, Dominican Republic} based on diaspora size + payout rail availability. Populate rows 47–52. | G11: Strategy | H11: In Progress
A12: 9 | B12: Add Western Union + MoneyGram as reference competitors | C12: P3 | D12: Low | E12: Current comparison only covers digital-first competitors. Legacy incumbents still hold significant US-originated remittance share and set the upper bound on 'expensive'. | F12: Insert 2 additional provider rows per corridor in the Comparison Matrix. Use same quote-capture cadence as recommendation #5. | G12: Ops | H12: In Progress
A13: 10 | B13: Track promotional first-transfer rates separately | C13: P3 | D13: Medium | E13: Remitly and Xoom regularly show promo FX on first transfer that is not sustainable (Methodology row 8). Comparing promo rates to steady-state pricing over-rewards competitors. | F13: Add a 'Promo / Steady-state' flag column to the Comparison Matrix. Only use steady-state rates for the ranking block. | G13: Analytics | H13: In Progress
A16: Executive Summary
A17: Win Nigeria / Ghana / Kenya on headline $0 fee to match TapTap Send. Win Mexico / Philippines / India on all-in cost by undercutting Remitly on fee and Xoom on FX. Ship a public calculator and automate the Guardrails — do not manage margin manually. Capture live competitor quotes weekly so the Comparison Matrix reflects reality, not marketing pages.

Sheet P1 Implementation
A1: P1 Implementation — Launch Pricing & Live-Quote Capture
A2: Operational tables for the 5 P1 recommendations. Yellow-tinted cells are inputs (edit these). White cells with formulas auto-recalculate. Send amount is USD 100 unless noted.
A4: P1-1 · Hero Corridor Launch — Nigeria, Ghana, Kenya at $0 Fee
A5: Match TapTap Send headline $0 fee. Recover margin inside a 0.75%–1.25% FX markup. Cells shaded yellow (#FFF9E6) are editable inputs.
A6: # | B6: Corridor | C6: Receive Currency | D6: Mid-Market FX (1 USD →) | E6: NexaRemit FX (1 USD →) | F6: FX Markup % | G6: NexaRemit Fee USD | H6: Recipient Amount | I6: All-in Cost to Sender USD | J6: Margin Check
A7: 1 | B7: Nigeria | C7: NGN | D7: 1650 | E7: 1633 | F7: =(D7-E7)/D7 -> 0.01030303 | G7: 0 | H7: =(100-G7)*E7 -> 163300 | I7: =100+G7 -> 100 | J7: =IF(((D7-E7)/D7*100)-0.35>=0,"OK ≥ $0.35","REVIEW") -> OK ≥ $0.35
A8: 2 | B8: Ghana | C8: GHS | D8: 15.2 | E8: 15.05 | F8: =(D8-E8)/D8 -> 0.0098684211 | G8: 0 | H8: =(100-G8)*E8 -> 1505 | I8: =100+G8 -> 100 | J8: =IF(((D8-E8)/D8*100)-0.35>=0,"OK ≥ $0.35","REVIEW") -> OK ≥ $0.35
A9: 3 | B9: Kenya | C9: KES | D9: 128.5 | E9: 127.2 | F9: =(D9-E9)/D9 -> 0.010116732 | G9: 0 | H9: =(100-G9)*E9 -> 12720 | I9: =100+G9 -> 100 | J9: =IF(((D9-E9)/D9*100)-0.35>=0,"OK ≥ $0.35","REVIEW") -> OK ≥ $0.35
A10: Guardrail: FX markup must cover ≥ $0.35 contribution margin at send=$100 (i.e., FX markup ≥ 0.35%). REVIEW flag means margin fails guardrail.
A12: P1-2 · Mexico (MXN) — Beat Remitly on All-in Cost
A13: Remitly typical fee is $1.99 to Mexico. Target: $0.99 fee + tighter FX. All-in cost must be lower than Remitly's.
A14: # | B14: Provider | C14: Fee USD | D14: Mid-Market FX | E14: Offered FX | F14: FX Markup % | G14: Recipient MXN | H14: All-in Cost USD | I14: Delta vs NexaRemit USD | J14: Verdict
A15: 1 | B15: NexaRemit (target) | C15: 0.99 | D15: 18.2 | E15: 18.02 | F15: =(D15-E15)/D15 -> 0.0098901099 | G15: =(100-C15)*E15 -> 1784.1602 | H15: =100+C15 -> 100.99 | I15: 0 | J15: Baseline
A16: 2 | B16: Remitly (published) | C16: 1.99 | D16: =D15 -> 18.2 | E16: 17.82 | F16: =(D16-E16)/D16 -> 0.020879121 | G16: =(100-C16)*E16 -> 1746.5382 | H16: =100+C16 -> 101.99 | I16: =H16-$H$15 -> 1 | J16: =IF(H16>$H$15,"NexaRemit wins","Adjust") -> NexaRemit wins
A17: 3 | B17: Xoom (published) | C17: 0 | D17: =D15 -> 18.2 | E17: 17.65 | F17: =(D17-E17)/D17 -> 0.03021978 | G17: =(100-C17)*E17 -> 1765 | H17: =100+C17 -> 100 | I17: =H17-$H$15 -> -0.99 | J17: =IF(H17>$H$15,"NexaRemit wins on FX","Adjust FX") -> Adjust FX
A18: 4 | B18: Wise (published) | D18: =D15 -> 18.2 | J18: Capture live quote (see P1-5)
A19: Verdict formula: NexaRemit wins when its all-in cost (H15) is LOWER than the competitor's all-in cost. If not, tighten FX or reduce fee and re-check.
A21: P1-3 · Philippines (PHP) — Beat Xoom on FX Spread
A22: Xoom markets $0 fee on eligible PH transactions but embeds FX spread. Target: $0.99 fee + ≤0.75% FX markup so all-in cost still beats Xoom.
A23: # | B23: Provider | C23: Fee USD | D23: Mid-Market FX | E23: Offered FX | F23: FX Markup % | G23: Recipient PHP | H23: All-in Cost USD | I23: Delta vs NexaRemit USD | J23: Verdict
A24: 1 | B24: NexaRemit (target) | C24: 0.99 | D24: 57.8 | E24: 57.37 | F24: =(D24-E24)/D24 -> 0.0074394464 | G24: =(100-C24)*E24 -> 5680.2037 | H24: =100+C24 -> 100.99 | I24: 0 | J24: Baseline
A25: 2 | B25: Xoom (published) | C25: 0 | D25: =D24 -> 57.8 | E25: 56.4 | F25: =(D25-E25)/D25 -> 0.024221453 | G25: =(100-C25)*E25 -> 5640 | H25: =100+C25 -> 100 | I25: =H25-$H$24 -> -0.99 | J25: =IF(G24>G25,"NexaRemit wins (more PHP delivered)","Tighten FX") -> NexaRemit wins (more PHP delivered)
A26: 3 | B26: Wise (published) | D26: =D24 -> 57.8 | J26: Capture live quote
A27: 4 | B27: Remitly (published) | D27: =D24 -> 57.8 | J27: Capture live quote
A28: When fees are both ~$0, the winner is whoever delivers MORE local currency (higher G). Use PHP recipient amount as the tie-breaker.
A30: P1-4 · India (INR) — Attack Xoom's FX Spread
A31: Xoom INR spread cited at 2.5%–4%. UPI/IMPS makes tight FX affordable. Target: $1.49 fee + ≤1.00% FX markup.
A32: # | B32: Provider | C32: Fee USD | D32: Mid-Market FX | E32: Offered FX | F32: FX Markup % | G32: Recipient INR | H32: All-in Cost USD | I32: Effective Cost % of Send | J32: Verdict
A33: 1 | B33: NexaRemit (target) | C33: 1.49 | D33: 83.2 | E33: 82.37 | F33: =(D33-E33)/D33 -> 0.0099759615 | G33: =(100-C33)*E33 -> 8114.2687 | H33: =100+C33 -> 101.49 | I33: =(C33+(D33-E33)/D33*100)/100 -> 0.024875962 | J33: Baseline
A34: 2 | B34: Xoom (low estimate) | C34: 0.3 | D34: =D33 -> 83.2 | E34: =D33*(1-0.025) -> 81.12 | F34: =(D34-E34)/D34 -> 0.025 | G34: =(100-C34)*E34 -> 8087.664 | H34: =100+C34 -> 100.3 | I34: =(C34+(D34-E34)/D34*100)/100 -> 0.028 | J34: =IF(I33<I34,"NexaRemit wins on all-in %","Tighten fee or FX") -> NexaRemit wins on all-in %
A35: 3 | B35: Xoom (high estimate) | C35: 0.3 | D35: =D33 -> 83.2 | E35: =D33*(1-0.04) -> 79.872 | F35: =(D35-E35)/D35 -> 0.04 | G35: =(100-C35)*E35 -> 7963.2384 | H35: =100+C35 -> 100.3 | I35: =(C35+(D35-E35)/D35*100)/100 -> 0.043 | J35: =IF(I33<I35,"NexaRemit wins on all-in %","Tighten fee or FX") -> NexaRemit wins on all-in %
A36: 4 | B36: Wise (published) | D36: =D33 -> 83.2 | J36: Capture live quote
A37: Effective Cost % = (Fee + FX Markup on $100) / Send. NexaRemit wins when its Effective Cost % is below both Xoom estimates.
A39: P1-5 · Weekly Live Competitor Quote Capture
A40: Weekly ops task: log into each competitor with send=$100 and capture Fee + FX. Paste values in yellow cells. All-in Cost, FX Markup %, and Winner are auto-calculated.
A41: # | B41: Week Of (Mon) | C41: Corridor | D41: Provider | E41: Fee USD | F41: Offered FX (1 USD →) | G41: Mid-Market FX (1 USD →) | H41: FX Markup % | I41: All-in Cost USD (fee + FX cost) | J41: Notes / Source URL
A42: 1 | B42: 2026-07-06 | C42: Nigeria | D42: NexaRemit | H42: =IF(AND(ISNUMBER(F42),ISNUMBER(G42),G42<>0),(G42-F42)/G42,"") | I42: =IF(AND(ISNUMBER(E42),ISNUMBER(F42),ISNUMBER(G42),G42<>0),E42+((G42-F42)/G42)*100,"")
A43: 2 | C43: Nigeria | D43: TapTap Send | H43: =IF(AND(ISNUMBER(F43),ISNUMBER(G43),G43<>0),(G43-F43)/G43,"") | I43: =IF(AND(ISNUMBER(E43),ISNUMBER(F43),ISNUMBER(G43),G43<>0),E43+((G43-F43)/G43)*100,"")
A44: 3 | C44: Nigeria | D44: Wise | H44: =IF(AND(ISNUMBER(F44),ISNUMBER(G44),G44<>0),(G44-F44)/G44,"") | I44: =IF(AND(ISNUMBER(E44),ISNUMBER(F44),ISNUMBER(G44),G44<>0),E44+((G44-F44)/G44)*100,"")
A45: 4 | C45: Nigeria | D45: Remitly | H45: =IF(AND(ISNUMBER(F45),ISNUMBER(G45),G45<>0),(G45-F45)/G45,"") | I45: =IF(AND(ISNUMBER(E45),ISNUMBER(F45),ISNUMBER(G45),G45<>0),E45+((G45-F45)/G45)*100,"")
...

Sheet P2 Implementation
A1: P2 Implementation — Calculator Spec · Guardrails · Next Corridor
A2: Operational tables for the 3 P2 recommendations. Yellow-tinted cells are inputs (edit these). White cells with formulas auto-recalculate.
A4: P2-6 · Public 'Total Cost' Calculator — Design Spec + Live Prototype
A5: Prototype the calculator logic here. When implemented on nexaremit.com/pricing it must show fee, FX markup, recipient amount, and savings vs each competitor with no login required.
A6: # | B6: Field / Competitor | C6: Value / Fee USD | D6: Mid-Market FX | E6: Offered FX | F6: FX Markup % | G6: Recipient Local | H6: All-in Cost USD | I6: Savings vs NexaRemit USD | J6: Winner Flag
A7: 1 | B7: Send Amount USD | C7: 100
A8: 2 | B8: Corridor (label only) | C8: Mexico (MXN)
A9: 3 | B9: NexaRemit fee USD | C9: 0.99 | D9: 18.2 | E9: 18.02 | F9: =(D9-E9)/D9 -> 0.0098901099 | G9: =(C7-C9)*E9 -> 1784.1602 | H9: =C7+C9 -> 100.99 | I9: 0 | J9: Baseline
A10: 4 | B10: Remitly | C10: 1.99 | D10: =D9 -> 18.2 | E10: 17.82 | F10: =(D10-E10)/D10 -> 0.020879121 | G10: =(C7-C10)*E10 -> 1746.5382 | H10: =C7+C10 -> 101.99 | I10: =H10-H9 -> 1 | J10: =IF(H10>H9,"NexaRemit saves","Adjust") -> NexaRemit saves
A11: 5 | B11: Xoom | C11: 0 | D11: =D9 -> 18.2 | E11: 17.65 | F11: =(D11-E11)/D11 -> 0.03021978 | G11: =(C7-C11)*E11 -> 1765 | H11: =C7+C11 -> 100 | I11: =H11-H9 -> -0.99 | J11: =IF(G9>G11,"NexaRemit delivers more MXN","Adjust FX") -> NexaRemit delivers more MXN
A12: 6 | B12: Wise | C12: 6.43 | D12: =D9 -> 18.2 | E12: =D9 -> 18.2 | F12: =(D12-E12)/D12 -> 0 | G12: =(C7-C12)*E12 -> 1702.974 | H12: =C7+C12 -> 106.43 | I12: =H12-H9 -> 5.44 | J12: =IF(H12>H9,"NexaRemit saves","Adjust") -> NexaRemit saves
A13: 7 | B13: WorldRemit | D13: =D9 -> 18.2 | J13: Capture live quote
A14: 8 | B14: TapTap Send | C14: 0 | D14: =D9 -> 18.2 | E14: 17.55 | F14: =(D14-E14)/D14 -> 0.035714286 | G14: =(C7-C14)*E14 -> 1755 | H14: =C7+C14 -> 100 | I14: =H14-H9 -> -0.99 | J14: =IF(G9>G14,"NexaRemit delivers more MXN","Adjust FX") -> NexaRemit delivers more MXN
A15: How this becomes production: the calculator page reads Send Amount + Corridor from the user, pulls Mid-Market FX from a public FX API, pulls Offered FX + Fee from NexaRemit's pricing service, and renders the same math shown in rows 9–14 with a live 'You save $X vs [Competitor]' line.
A17: Calculator UX Requirements
A18: # | B18: Requirement | C18: Description | G18: Acceptance Criteria | I18: Priority | J18: Owner
A19: 1 | B19: No login required | C19: Anonymous visitor can get a full quote | G19: Zero auth prompts before result render | I19: Must | J19: Product
A20: 2 | B20: Mid-market reference visible | C20: Show mid-market rate next to offered rate | G20: Both rates visible in same viewport | I20: Must | J20: Product
A21: 3 | B21: Live competitor delta | C21: 'You save $X vs [Remitly/Xoom/Wise]' displayed per corridor | G21: Delta refreshes when user changes amount/corridor | I21: Must | J21: Product + Data
A22: 4 | B22: Corridor picker | C22: Dropdown of all supported corridors | G22: All 6 corridors + 'Other coming soon' entry | I22: Must | J22: Product
A23: 5 | B23: Shareable URL | C23: Quote result deep-linkable (query params) | G23: /pricing?send=100&corridor=MXN opens with values pre-filled | I23: Should | J23: Engineering
A24: 6 | B24: Mobile-first layout | C24: Single column at ≤640px, side-by-side ≥1024px | G24: Lighthouse mobile score ≥ 90 | I24: Should | J24: Design + Eng
A26: P2-7 · Guardrails-as-Code — Pricing Service Rules
A27: Enforce these rules automatically in the pricing service. Do not review manually in a spreadsheet. Each rule has a trigger, action, and severity.
A28: # | B28: Rule Name | C28: Trigger Condition | D28: Action | E28: Severity | F28: Alert Channel | G28: Owner | H28: Test Method | I28: Live Status | J28: Notes
A29: 1 | B29: Minimum margin | C29: Quote contribution margin < $0.35 | D29: Reject quote; return HTTP 422 | E29: Critical | F29: PagerDuty | G29: Engineering | H29: Unit test: mock quote with margin=$0.30 must throw | I29: Not implemented | J29: Applies to every corridor at send ≥ $50
A30: 2 | B30: FX markup cap (Hero) | C30: Offered FX markup > 1.25% on NGN/GHS/KES | D30: Reject quote; auto-page pricing on-call | E30: Critical | F30: PagerDuty | G30: Engineering | H30: Integration test per hero corridor | I30: Not implemented | J30: Hero corridors capped tighter than core
A31: 3 | B31: FX markup cap (Core) | C31: Offered FX markup > 1.00% on PHP/MXN/INR | D31: Reject quote; log warn | E31: High | F31: Slack #pricing-alerts | G31: Engineering | H31: Integration test per core corridor | I31: Not implemented | J31: Core corridors get slightly wider band than hero
A32: 4 | B32: Hero loss cap | C32: Cumulative Hero corridor loss for month > marketing budget | D32: Auto-flag corridor for review; pause promo FX | E32: High | F32: Slack + email to Growth lead | G32: Growth + Finance | H32: Nightly job compares MTD loss vs budget row | I32: Not implemented | J32: Reset first of each month
A33: 5 | B33: Tier-move trigger (to Core) | C33: 3 consecutive months of negative unit margin on any corridor | D33: Auto-flag corridor to move from Hero → Core | E33: Medium | F33: Slack #pricing-alerts | G33: Pricing | H33: Monthly cron job on financial data | I33: Not implemented | J33: Reference: NexaRemit Strategy row 16
A34: 6 | B34: Tier-move trigger (to Hero) | C34: Corridor monthly volume > threshold AND competitor headline fee = $0 | D34: Auto-flag corridor to move Core → Hero | E34: Medium | F34: Slack #pricing-alerts | G34: Pricing + Growth | H34: Monthly cron job on volume + competitor scrape | I34: Not implemented | J34: Reference: NexaRemit Strategy row 17
A35: 7 | B35: Promo abuse detector | C35: Same user creates > 3 first-transfer promo quotes in 30 days | D35: Block promo FX; charge steady-state rate | E35: High | F35: Slack #fraud-alerts | G35: Risk + Engineering | H35: Weekly sample audit | I35: Not implemented | J35: Prevent Remitly-style promo drain
A36: 8 | B36: Competitor fee gap alert | C36: Competitor headline fee drops > $0.50 below NexaRemit for same corridor | D36: Alert pricing lead; propose new fee within 48h | E36: Medium | F36: Email daily digest | G36: Pricing | H36: Uses Weekly Quote Capture from P1-5 | I36: Not implemented | J36: Prevents surprise loss of price leadership
A37: Definition of done for P2-7: every rule row has Live Status = 'Live' with test evidence linked in the Notes column.
A39: P2-8 · Next-Corridor Scorecard — Which Market to Launch
A40: Weighted score across 5 dimensions. Higher = better candidate. Weights sum to 100%. Adjust weights in row 43 (yellow cells) to run sensitivity analysis.
B42: Dimension → | C42: Diaspora Size (US) | D42: Payout Rail Readiness | E42: Competitive Intensity (inverse) | F42: Regulatory Ease | G42: Avg Send Amount | H42: TOTAL WEIGHT
A43: Weight % | C43: 0.3 | D43: 0.2 | E43: 0.2 | F43: 0.15 | G43: 0.15 | H43: =SUM(C43:G43) -> 1
A44: Score each candidate 1–10 per dimension in the yellow cells below. Weighted Score = SUMPRODUCT of scores × weights above.
A45: # | B45: Candidate Corridor | C45: Diaspora Size | D45: Payout Rails | E45: Comp. Intensity (inv) | F45: Regulatory Ease | G45: Avg Send | H45: Weighted Score | I45: Rank | J45: Notes
...

Sheet P3 Implementation
A1: P3 Implementation — Legacy Benchmarks · Promo-vs-Steady-State Tracking
A2: Operational tables for the 2 P3 recommendations. Yellow-tinted cells are inputs (edit these). White cells with formulas auto-recalculate.
A4: P3-9 · Legacy Competitor Benchmark — Western Union & MoneyGram
A5: Establish the upper bound on 'expensive'. WU and MoneyGram set the reference incumbents. Use this delta in marketing ('save up to $X vs Western Union').
A6: # | B6: Corridor | C6: Provider | D6: Fee USD | E6: Offered FX (1 USD →) | F6: Mid-Market FX | G6: FX Markup % | H6: All-in Cost USD | I6: Delta vs NexaRemit Target USD | J6: Notes / Source URL
A7: 1 | B7: Nigeria (NGN) | C7: Western Union | G7: =IF(AND(ISNUMBER(E7),ISNUMBER(F7),F7<>0),(F7-E7)/F7,"") | H7: =IF(AND(ISNUMBER(D7),ISNUMBER(E7),ISNUMBER(F7),F7<>0),D7+((F7-E7)/F7)*100,"") | I7: =IF(ISNUMBER(H7),H7-100.75,"")
A8: 2 | B8: Nigeria (NGN) | C8: MoneyGram | G8: =IF(AND(ISNUMBER(E8),ISNUMBER(F8),F8<>0),(F8-E8)/F8,"") | H8: =IF(AND(ISNUMBER(D8),ISNUMBER(E8),ISNUMBER(F8),F8<>0),D8+((F8-E8)/F8)*100,"") | I8: =IF(ISNUMBER(H8),H8-100.75,"")
A9: 3 | B9: Ghana (GHS) | C9: Western Union | G9: =IF(AND(ISNUMBER(E9),ISNUMBER(F9),F9<>0),(F9-E9)/F9,"") | H9: =IF(AND(ISNUMBER(D9),ISNUMBER(E9),ISNUMBER(F9),F9<>0),D9+((F9-E9)/F9)*100,"") | I9: =IF(ISNUMBER(H9),H9-100.75,"")
A10: 4 | B10: Ghana (GHS) | C10: MoneyGram | G10: =IF(AND(ISNUMBER(E10),ISNUMBER(F10),F10<>0),(F10-E10)/F10,"") | H10: =IF(AND(ISNUMBER(D10),ISNUMBER(E10),ISNUMBER(F10),F10<>0),D10+((F10-E10)/F10)*100,"") | I10: =IF(ISNUMBER(H10),H10-100.75,"")
A11: 5 | B11: Kenya (KES) | C11: Western Union | G11: =IF(AND(ISNUMBER(E11),ISNUMBER(F11),F11<>0),(F11-E11)/F11,"") | H11: =IF(AND(ISNUMBER(D11),ISNUMBER(E11),ISNUMBER(F11),F11<>0),D11+((F11-E11)/F11)*100,"") | I11: =IF(ISNUMBER(H11),H11-100.75,"")
A12: 6 | B12: Kenya (KES) | C12: MoneyGram | G12: =IF(AND(ISNUMBER(E12),ISNUMBER(F12),F12<>0),(F12-E12)/F12,"") | H12: =IF(AND(ISNUMBER(D12),ISNUMBER(E12),ISNUMBER(F12),F12<>0),D12+((F12-E12)/F12)*100,"") | I12: =IF(ISNUMBER(H12),H12-100.75,"")
A13: 7 | B13: Mexico (MXN) | C13: Western Union | G13: =IF(AND(ISNUMBER(E13),ISNUMBER(F13),F13<>0),(F13-E13)/F13,"") | H13: =IF(AND(ISNUMBER(D13),ISNUMBER(E13),ISNUMBER(F13),F13<>0),D13+((F13-E13)/F13)*100,"") | I13: =IF(ISNUMBER(H13),H13-101.49,"")
A14: 8 | B14: Mexico (MXN) | C14: MoneyGram | G14: =IF(AND(ISNUMBER(E14),ISNUMBER(F14),F14<>0),(F14-E14)/F14,"") | H14: =IF(AND(ISNUMBER(D14),ISNUMBER(E14),ISNUMBER(F14),F14<>0),D14+((F14-E14)/F14)*100,"") | I14: =IF(ISNUMBER(H14),H14-101.49,"")
A15: 9 | B15: Philippines (PHP) | C15: Western Union | G15: =IF(AND(ISNUMBER(E15),ISNUMBER(F15),F15<>0),(F15-E15)/F15,"") | H15: =IF(AND(ISNUMBER(D15),ISNUMBER(E15),ISNUMBER(F15),F15<>0),D15+((F15-E15)/F15)*100,"") | I15: =IF(ISNUMBER(H15),H15-101.49,"")
A16: 10 | B16: Philippines (PHP) | C16: MoneyGram | G16: =IF(AND(ISNUMBER(E16),ISNUMBER(F16),F16<>0),(F16-E16)/F16,"") | H16: =IF(AND(ISNUMBER(D16),ISNUMBER(E16),ISNUMBER(F16),F16<>0),D16+((F16-E16)/F16)*100,"") | I16: =IF(ISNUMBER(H16),H16-101.49,"")
A17: 11 | B17: India (INR) | C17: Western Union | G17: =IF(AND(ISNUMBER(E17),ISNUMBER(F17),F17<>0),(F17-E17)/F17,"") | H17: =IF(AND(ISNUMBER(D17),ISNUMBER(E17),ISNUMBER(F17),F17<>0),D17+((F17-E17)/F17)*100,"") | I17: =IF(ISNUMBER(H17),H17-101.99,"")
A18: 12 | B18: India (INR) | C18: MoneyGram | G18: =IF(AND(ISNUMBER(E18),ISNUMBER(F18),F18<>0),(F18-E18)/F18,"") | H18: =IF(AND(ISNUMBER(D18),ISNUMBER(E18),ISNUMBER(F18),F18<>0),D18+((F18-E18)/F18)*100,"") | I18: =IF(ISNUMBER(H18),H18-101.99,"")
A19: Delta column shows how much more (positive) or less (negative) the legacy provider costs vs NexaRemit's target all-in cost. Positive = marketing headline ('save $X vs Western Union').
A21: Marketing Headline Auto-Generator
A22: # | B22: Corridor | C22: Best Legacy Reference | D22: Legacy All-in Cost | E22: NexaRemit Target | F22: Savings USD | G22: Savings % | H22: Suggested Headline
A23: 1 | B23: Nigeria | C23: Higher of WU/MG | D23: =_xlfn.IFERROR(MAX(H7,H8),"") -> 0 | E23: 100.75 | F23: =_xlfn.IFERROR(D23-E23,"") -> -100.75 | G23: =_xlfn.IFERROR((D23-E23)/E23,"") -> -1 | H23: =IF(ISNUMBER(F23),"Send to Nigeria and save $"&TEXT(F23,"0.00")&" vs Western Union — no transfer fees.","Fill quote to generate headline") -> Send to Nigeria and save $-100.75 vs Western Union — no transfer fees.
A24: 2 | B24: Ghana | C24: Higher of WU/MG | D24: =_xlfn.IFERROR(MAX(H9,H10),"") -> 0 | E24: 100.75 | F24: =_xlfn.IFERROR(D24-E24,"") -> -100.75 | G24: =_xlfn.IFERROR((D24-E24)/E24,"") -> -1 | H24: =IF(ISNUMBER(F24),"Send to Ghana and save $"&TEXT(F24,"0.00")&" vs Western Union — no transfer fees.","Fill quote to generate headline") -> Send to Ghana and save $-100.75 vs Western Union — no transfer fees.
A25: 3 | B25: Kenya | C25: Higher of WU/MG | D25: =_xlfn.IFERROR(MAX(H11,H12),"") -> 0 | E25: 100.75 | F25: =_xlfn.IFERROR(D25-E25,"") -> -100.75 | G25: =_xlfn.IFERROR((D25-E25)/E25,"") -> -1 | H25: =IF(ISNUMBER(F25),"Send to Kenya and save $"&TEXT(F25,"0.00")&" vs Western Union — no transfer fees.","Fill quote to generate headline") -> Send to Kenya and save $-100.75 vs Western Union — no transfer fees.
A26: 4 | B26: Mexico | C26: Higher of WU/MG | D26: =_xlfn.IFERROR(MAX(H13,H14),"") -> 0 | E26: 101.49 | F26: =_xlfn.IFERROR(D26-E26,"") -> -101.49 | G26: =_xlfn.IFERROR((D26-E26)/E26,"") -> -1 | H26: =IF(ISNUMBER(F26),"Send to Mexico for $0.99 and save $"&TEXT(F26,"0.00")&" vs Western Union.","Fill quote to generate headline") -> Send to Mexico for $0.99 and save $-101.49 vs Western Union.
A27: 5 | B27: Philippines | C27: Higher of WU/MG | D27: =_xlfn.IFERROR(MAX(H15,H16),"") -> 0 | E27: 101.49 | F27: =_xlfn.IFERROR(D27-E27,"") -> -101.49 | G27: =_xlfn.IFERROR((D27-E27)/E27,"") -> -1 | H27: =IF(ISNUMBER(F27),"Send to the Philippines for $0.99 and save $"&TEXT(F27,"0.00")&" vs Western Union.","Fill quote to generate headline") -> Send to the Philippines for $0.99 and save $-101.49 vs Western Union.
A28: 6 | B28: India | C28: Higher of WU/MG | D28: =_xlfn.IFERROR(MAX(H17,H18),"") -> 0 | E28: 101.99 | F28: =_xlfn.IFERROR(D28-E28,"") -> -101.99 | G28: =_xlfn.IFERROR((D28-E28)/E28,"") -> -1 | H28: =IF(ISNUMBER(F28),"Send to India for $1.49 and save $"&TEXT(F28,"0.00")&" vs Western Union.","Fill quote to generate headline") -> Send to India for $1.49 and save $-101.99 vs Western Union.
A30: P3-10 · Promo vs Steady-State Rate Tracking
A31: Remitly and Xoom offer promotional first-transfer rates that are not sustainable. Separate promo quotes from steady-state so rankings reflect actual repeat-user pricing.
A33: Classification Rules — When to Flag a Quote as 'Promo'
A34: # | B34: Rule | C34: Trigger | D34: Description | G34: Auto-Flag Value | H34: Applies To | I34: Confidence | J34: Notes
A35: 1 | B35: First-transfer marker | C35: Page shows 'special rate on first transfer' | D35: Quote explicitly labeled as new-user promotional rate on landing page or checkout | G35: Promo | H35: Remitly, Xoom, WorldRemit | I35: High | J35: Most explicit signal
A36: 2 | B36: FX better than mid-market | C36: Offered FX ≥ mid-market rate | D36: If Offered FX equals or exceeds the mid-market rate, the provider is subsidizing FX — promo behavior | G36: Promo | H36: Any provider | I36: High | J36: Sustainable providers always take some FX spread
A37: 3 | B37: FX markup < 0.10% | C37: Offered FX markup below 0.10% | D37: Extremely tight FX spread indicates loss-leader promo pricing | G37: Promo | H37: Any provider | I37: Medium | J37: Wise legitimately runs tight but rarely below 0.10%
A38: 4 | B38: Fee = $0 + tight FX | C38: Fee=$0 AND FX markup < 0.50% | D38: Combination of no fee and near-mid-market FX is almost always promotional | G38: Promo | H38: Any provider | I38: Medium | J38: TapTap steady-state has fee=$0 but wider FX
A39: 5 | B39: Repeat capture check | C39: Same corridor/provider quote taken 4 weeks apart differ by > 1.5% | D39: If steady-state price drifts materially week-over-week, prior weeks were promo | G39: Reclassify prior as Promo | H39: Any provider | I39: Medium | J39: Requires 4+ weeks of Weekly Quote Capture history
A40: 6 | B40: Explicit disclaimer | C40: Provider footer states 'promotional', 'introductory', 'limited time' | D40: Language on the quote or checkout screen that explicitly describes the pricing as temporary | G40: Promo | H40: Any provider | I40: High | J40: Screenshot for evidence
A41: A quote flagged 'Promo' by ANY rule above is excluded from steady-state ranking. Reclassification is manual — apply the rule label in the log below.
A43: Classified Quote Log — Promo vs Steady-State
A44: # | B44: Week Of | C44: Corridor | D44: Provider | E44: Fee USD | F44: FX Markup % | G44: All-in Cost USD | H44: Classification | I44: Rule Applied | J44: Notes / Screenshot URL
A45: 1 | B45: 2026-07-06 | C45: Mexico | D45: Remitly | E45: 1.99 | F45: 0.005 | G45: =IF(AND(ISNUMBER(E45),ISNUMBER(F45)),E45+F45*100,"") -> 2.49 | H45: Steady-state | I45: N/A | J45: Second-time user quote — matches published $1.99 baseline
...
